Workbook

Sheet TEST_NYC_Coding
A1: NYC Coding — GenAI Policy Coding
A4: ID | B4: Tier | C4: Region | D4: Jurisdiction / Institution | E4: Institution | F4: Document Title | G4: Document Type | H4: Publication Date | I4: Source URL | J4: Stance | K4: Disclosure | L4: Discretion | M4: Focus (Primary) | N4: Focus (Secondary) | O4: Enforcement | P4: Coverage | Q4: Key Quote (verbatim) | R4: Coder Notes | S4: Coder | T4: Date Coded | U4: Coder Agreement (Initials if agree and DONT AGREE)
A5: NYC-001 | B5: National/Federal | C5: NYC | D5: U.S. Office of Management and Budget | F5: OMB M-25-21: Accelerating Federal Use of AI through Innovation, Governance, and Public Trust | G5: Official Guidance | H5: 45750 | I5: https://www.whitehouse.gov/wp-content/uploads/2025/02/M-25-21-Accelerating-Federal-Use-of-AI-through-Innovation-Governance-and-Public-Trust.pdf | J5: Functional | K5: Not specified | L5: Gov-mandated | M5: Privacy/Data/Ethics | N5: Professional Readiness | O5: Guidance only | P5: All community | Q5: “Agencies are directed to accelerate the Federal use of AI by focusing on three key priorities: innovation, governance, and public trust.” | S5: EY | T5: 46141
A6: NYC-002 | B6: National/Federal | C6: NYC | D6: U.S. Department of Education | F6: U.S. Department of Education Dear Colleague Letter on AI and Education Outcomes | G6: Official Guidance | H6: 45860 | I6: https://www.ed.gov/media/document/opepd-ai-dear-colleague-letter-7222025-110427.pdf | J6: Encouraging | K6: Not specified | L6: Hybrid/Mixed | M6: Pedagogy/Learning | N6: AI Literacy | O6: Guidance only | P6: Both | Q6: “The Department encourages grantees to explore how AI can enhance teaching and learning, expand access, and support educators, without replacing the critical role they play.” | S6: EY | T6: 46141
A7: NYC-003 | B7: National/Federal | C7: NYC | D7: U.S. Federal Government | F7: Removing Barriers to American Leadership in Artificial Intelligence | G7: Executive Order | H7: 45680 | I7: https://www.whitehouse.gov/presidential-actions/2025/01/removing-barriers-to-american-leadership-in-artificial-intelligence/ | J7: Encouraging | K7: Not specified | L7: Gov-mandated | M7: Professional Readiness | N7: AI Literacy | O7: Guidance only | P7: All community | Q7: "It is the policy of the United States to sustain and enhance America’s global AI dominance in order to promote human flourishing, economic competitiveness, and national security." | S7: EY | T7: 46137
A8: NYC-004 | B8: National/Federal | C8: NYC | D8: U.S. Department of Education | F8: Artificial Intelligence and the Future of Teaching and Learning | G8: Official Guidance | H8: 45047 | I8: https://www.ed.gov/sites/ed/files/documents/ai-report/ai-report.pdf | J8: Cautious | K8: Recommended | L8: Not specified | M8: Pedagogy/Learning | N8: Equity | O8: Guidance only | P8: All community | Q8: "In summary, it is imperative to address AI in education now to realize key opportunities, prevent and mitigate emergent risks, and tackle unintended consequences." | S8: EY | T8: 46137
A9: NYC-005 | B9: National/Federal | C9: NYC | D9: National Institute of Standards and Technology (NIST) | F9: Artificial Intelligence Risk Management Framework: Generative Artificial Intelligence Profile | G9: Official Guidance | H9: 45499 | I9: https://doi.org/10.6028/NIST.AI.600-1 | J9: Cautious | K9: Recommended | L9: Not specified | M9: Privacy/Data/Ethics | N9: AI Literacy | O9: Guidance only | P9: All community | Q9: "This document defines risks that are novel to or exacerbated by the use of GAI. After introducing and describing these risks, the document provides a set of suggested actions to help organizations govern, map, measure, and manage these risks." | R9: This document has a multilevel analysis of different aspects of Gen AI, the key quote might not be enough to summarize all the ideas in the document. | S9: EY | T9: 46137
A10: NYC-006 | B10: State/Territory | C10: NYC | D10: Office of the State Comptroller; Division of State Government Accountability | F10: New York State Artificial Intelligence Governance Audit | G10: Other | H10: 45750 | I10: https://www.osc.ny.gov/state-agencies/audits/2025/04/03/new-york-state-artificial-intelligence-governance?utm_source=chatgpt.com | J10: Cautious | K10: Recommended | L10: Not specified | M10: Privacy/Data/Ethics | N10: AI Literacy | O10: Guidance only | P10: All community | Q10: NYS does not have an effective AI governance framework. While the AI Policy outlines certain requirements or recommendations for agencies to consider, it lacks adequate guidance and procedures on how these agencies can meet these expectations. | S10: EY | T10: 46137
A11: NYC-007 | B11: State/Territory | C11: NYC | D11: New York City Office of Technology and Innovation (OTI) | F11: AI Public Participation & Engagement Guidance | G11: Official Guidance | H11: 46006 | I11: https://www.nyc.gov/assets/oti/downloads/pdf/NYC-OTI_Guidance_AI-Public-Participation-and-Engagement.pdf | J11: Cautious | K11: Recommended | L11: Hybrid/Mixed | M11: Equity | N11: Privacy/Data/Ethics | O11: Guidance only | P11: All community | Q11: "As AI tools are increasingly used and incorporated into agencies’ existing software and systems, a careful consideration of varied real or potential public impacts will be critical. Agencies should seek to integrate meaningful public participation and engagement, where appropriate, to understand these impacts, mitigate risk, support trust and transparency, and facilitate successful development and roll-out that serves the needs and interests of New Yorkers." | S11: EY | T11: 46137
A12: NYC-008 | B12: State/Territory | C12: NYC | D12: New York City Office of Technology and Innovation (OTI) | F12: NYC Use Guidance: Generative Artificial Intelligence | G12: Official Guidance | H12: 46021 | I12: https://www.nyc.gov/assets/oti/downloads/pdf/New-York-City-Generative-AI-Use-Guidance.pdf | J12: Cautious | K12: Required | L12: Hybrid/Mixed | M12: Privacy/Data/Ethics | N12: AI Literacy | O12: Guidance only | P12: All community | Q12: "The City is committed to a responsible approach to emerging technologies. This Use Guidance provides a framework for the responsible use of GenAI by City personnel, aligned with the City’s AI Principles, and applicable laws and policies." | S12: EY | T12: 46137
A13: NYC-009 | B13: State/Territory | C13: NYC | D13: New York State Office of Information Technology Services (ITS) | F13: NYS ITS Acceptable Use of Artificial Intelligence Technologies | G13: Official Guidance | H13: 45292 | I13: https://its.ny.gov/system/files/documents/2026/01/nys-p24-001-acceptable-use-of-ai.pdf | J13: Cautious | K13: Required | L13: Hybrid/Mixed | M13: Privacy/Data/Ethics | N13: Equity | O13: Guidance only | P13: All community | Q13: "Through the responsible use of AI, SEs can drive innovation, increase operational efficiencies, and better serve New Yorkers while protecting privacy, managing risk, and promoting accountability, safety, and equity. Agencies are encouraged to responsibly adopt AI technologies and should consider this policy a tool to aid in that adoption." | S13: EY | T13: 46137
A14: NYC-010 | B14: Institutional | C14: NYC | D14: Columbia University | E14: Columbia | F14: Generative AI Policy (Office of the Provost) | G14: University Policy | H14: 2025 | I14: https://provost.columbia.edu/content/office-senior-vice-provost/ai-policy | J14: Cautious | K14: Required | L14: Hybrid/Mixed | M14: Academic Integrity | N14: Privacy/Data/Ethics | O14: Referenced to integrity code | P14: Both | Q14: "Generative AI tools have the capacity to expedite existing processes and make possible new ones. These tools also have the potential to foster student learning and advance many aspects of research and health care delivery. While the University supports the responsible use of AI, these novel tools have notable limitations and present new risks that must be taken into consideration when using these technologies." | S14: EY | T14: 46137
A15: NYC-011 | B15: Institutional | C15: NYC | D15: Columbia University | E15: Columbia | F15: Best Practices for Responsible AI Use | G15: University Policy | H15: 46031 | I15: https://etc.cuit.columbia.edu/news/best-practices-responsible-ai-use | J15: Functional | K15: Conditional | L15: Instructor decides | M15: Privacy/Data/Ethics | N15: AI Literacy | O15: Guidance only | P15: Both | Q15: CUIT’s guidance is designed to help the Columbia community benefit from AI while avoiding common failure points, particularly when institutional or sensitive data is involved.
A16: NYC-012 | B16: Institutional | C16: NYC | D16: New York University | E16: NYU | F16: Teaching with Generative AI — NYU FAQ | G16: University Policy | H16: 45708 | I16: https://www.nyu.edu/faculty/teaching-and-learning-resources/teaching-with-generative-tools/frequently-asked-questions.html | J16: Functional | K16: Recommended | L16: Instructor decides | M16: Pedagogy/Learning | N16: Academic Integrity | O16: Explicit penalties | P16: Faculty only | Q16: "Generative AI is a new arrival in the academic environment and can be used in a wide variety of ways. Because of this novelty and flexibility, there are few standard approaches to its use beyond an Faculty/Inst. decides restriction on taking credit for AI output without acknowledging its use. Most policies will be set by the schools or by individual faculty members." | S16: EY | T16: 46137
A17: NYC-013 | B17: Faculty/School | C17: NYC | D17: New York University | E17: NYU | F17: Academic Integrity and Syllabus Support in the Age of Generative AI | G17: University Policy | H17: 2025 | I17: https://steinhardt.nyu.edu/faculty-and-staff/academic-affairs/steinhardt-ai-hub/academic-integrity-and-syllabus-support-age | J17: Functional | K17: Recommended | L17: Instructor decides | M17: Academic Integrity | N17: Pedagogy/Learning | O17: Referenced to integrity code | P17: Faculty only | Q17: "Creating clear policies around AI use is essential to maintaining academic integrity and setting student expectations. These policies should outline when and how AI tools like ChatGPT, Perplexity.ai, or Grammarly can be used and ensure students understand the ethical implications of AI in academic work." | S17: EY | T17: 46137
A18: NYC-014 | B18: Faculty/School | C18: NYC | D18: New York University (Stern) | E18: NYU | F18: Teaching and Learning with Generative AI at NYU Stern | G18: Library Guide | I18: https://sites.google.com/stern.nyu.edu/teaching-learning-gen-ai/home | J18: Functional | K18: Recommended | L18: Instructor decides | M18: AI Literacy | N18: Pedagogy/Learning | O18: Referenced to integrity code | P18: Both | Q18: “This resource was created by the Learning Science Lab to support the NYU Stern community in thinking deliberately about the use of generative AI (genAI) and other related technologies as they arise.” | S18: EY | T18: 46137
A19: NYC-015 | B19: Faculty/School | C19: NYC | D19: New York University (Tisch School of the Arts) | E19: NYU | F19: Tisch Academic Integrity | G19: University Policy | H19: 2026 | I19: https://tisch.nyu.edu/faculty/academic-integ | J19: Cautious | K19: Not specified | L19: Instructor decides | M19: Academic Integrity | N19: Pedagogy/Learning | O19: Explicit penalties | P19: Both | Q19: Generative AI: Please note, with recent developments in technologies like ChatGPT, the existence of a well-written paragraph is no longer evidence of human effort. To read the Provost's notes on how to adapt writing assignments in the age of generative AI, click here. | S19: EY | T19: 46143
A20: NYC-016 | B20: Faculty/School | C20: NYC | D20: New York University (Tisch School of the Arts Provost) | E20: NYU | F20: Adapting Writing Assignments to Generative AI | G20: FAQ/Resource Page | I20: https://docs.google.com/document/d/1CbWKCBCMuO1kJlsK-ukD5lXGVuKuSzq8H8MFAQVvdDM/edit?usp=sharing | J20: Functional | K20: Recommended | L20: Instructor decides | M20: AI Literacy | N20: Academic Integrity | O20: Referenced to integrity code | P20: Faculty only | Q20: Even if an instructor does not intend to change individual assignments, the availability and generality of these tools increases the need for clarity around the instructor’s expectations. Whatever strategies an instructor might adopt for individual assignments or a whole course, instructors should explain to students what is expected around AI use. | S20: EY | T20: 46143
A21: NYC-017 | B21: Institutional | C21: NYC | D21: City University of New York (CUNY) | E21: CUNY | F21: CUNY AI Academic Hub (General) | G21: University Policy | H21: 2025 | I21: https://www.cuny.edu/academics/ai-academic-hub/ | J21: Encouraging | K21: Not specified | L21: Not specified | M21: AI Literacy | N21: Professional Readiness | O21: Guidance only | P21: Both | Q21: "Our Vision is shaping the Future of Human-AI Powered Education. CUNY is at the forefront of AI-driven transformation in higher education. Our mission is to harness AI’s potential to empower learning, drive research, and foster innovation—ensuring equitable opportunities for all." | S21: EY | T21: 46137
A22: NYC-018 | B22: Faculty/School | C22: NYC | D22: Baruch College (CUNY) | E22: CUNY | F22: Guidelines for AI Use at Baruch College | G22: University Policy | H22: 45888 | I22: https://provost.baruch.cuny.edu/artificial-intelligence-think-tank/ai-use-guidance/ | J22: Encouraging | K22: Required | L22: Instructor decides | M22: Pedagogy/Learning | N22: Privacy/Data/Ethics | O22: Referenced to integrity code | P22: Both | Q22: "Faculty are encouraged to integrate artificial intelligence education into their courses as appropriate to their disciplines, but are not obligated to do so. All syllabi should include a course- and discipline-appropriate policy on the use of generative AI." | S22: EY | T22: 46138
A23: NYC-019 | B23: Faculty/School | C23: NYC | D23: Kingsborough Community College (CUNY) | E23: CUNY | F23: Kingsborough Community College Academic Integrity Policy | G23: University Policy | H23: 2025 | I23: https://www.kbcc.cuny.edu/studentaffairs/student_conduct/academic_integrity.html | J23: Cautious | K23: Required | L23: Faculty/Inst. decides | M23: Academic Integrity | N23: Equity | O23: Referenced to integrity code | P23: Students only | Q23: "Example of cheating include: (...) Submitting content generated by another person or an AI tool or any other source as solely your own work as your own, including, but not limited to, material obtained in whole or in part from commercial study or homework help websites, or content generated or altered by AI or digital paraphrasing tools without proper citation." | S23: EY | T23: 46137
A24: NYC-020 | B24: Institutional | C24: NYC | D24: The City College of New York (CUNY) | E24: CUNY | F24: AI Across CUNY | G24: University Policy | H24: 2025 | I24: https://www.ccny.cuny.edu/tlc/making-your-course-available?srsltid=AfmBOoojIHHL2OxDCdrK-0Xc9elMyrAnNWVcOtEzwybtMdTvH4Pbcfy- | J24: Functional | K24: Required | L24: Instructor decides | M24: AI Literacy | N24: Pedagogy/Learning | O24: Referenced to integrity code | P24: Both | Q24: "Our goal is to provide a collaborative space for sharing effective strategies for the responsible and critical use of AI, particularly within the CUNY community." | S24: EY | T24: 46137
A25: NYC-021 | B25: Faculty/School | C25: NYC | D25: Hunter College (CUNY) | E25: CUNY | F25: CUNY Academic Integrity Policy | G25: University Policy | I25: https://www.hunter.cuny.edu/center-for-digital-learning-and-innovative-pedagogy/online-learning-resources/academic-integrity-policy/ | J25: Cautious | K25: Required | L25: Instructor decides | M25: Academic Integrity | N25: Professional Readiness | O25: Explicit penalties | P25: Both | Q25: Preparing students to learn from and use AI responsibly and ethically is critical to the University’s mission, to ensuring academic integrity, to securing the rigor of the University’s academic programs. Further, students must become facile with the use of AI to learn effectively in today’s world and to prepare for their AI-assisted careers and lives in the future. | S25: EY | T25: 46143
A26: NYC-022 | B26: Faculty/School | C26: NYC | D26: Queens College (CUNY) | E26: CUNY | F26: Generative AI in the Classroom: Best Practices, a CETLL Guide | G26: FAQ/Resource Page | H26: 45717 | I26: https://www.qc.cuny.edu/cetll/wp-content/uploads/sites/138/2026/03/Generative-AI-in-the-Classroom-Best-Practices-a-CETLL-Guide_ACCESSIBLE_3.19.pdf | J26: Functional | K26: Recommended | L26: Instructor decides | M26: Pedagogy/Learning | N26: AI Literacy | O26: Guidance only | P26: Faculty only | Q26: Currently, there is no specific CUNY or QC policy on the use of artificial intelligence in the classroom outside of mentions of AI in the CUNY Academic Integrity Policy. This means that, as instructors, we have a lot of flexibility and responsibility to consider how and when the use of generative AI is acceptable in our classes to clearly communicate these parameters to our students as we prepare them for the integration of these technologies in work and life.
A27: NYC-023 | B27: Faculty/School | C27: NYC | D27: Teachers College, Columbia University | E27: Columbia | F27: Recommendations for Generative AI Use for teaching at TC | G27: FAQ/Resource Page | H27: 2025 | I27: https://www.tc.columbia.edu/digitalfuturesinstitute/ai-in-education/recommendations-for-generative-ai-use-at-tc/ | J27: Functional | K27: Conditional | L27: Instructor decides | M27: Pedagogy/Learning | N27: Academic Integrity | O27: Referenced to integrity code | P27: Both | Q27: "TC provides flexibility for instructors to experiment with and use generative AI in their courses. Each TC instructor should set specific policies about student use of generative AI for their course assignments" | S27: EY | T27: 46137
A28: NYC-024 | B28: Course-wide | C28: NYC | D28: Columbia Course 1 | E28: Columbia | F28: CSEE 4119: Introduction to Computer Networks | G28: Syllabus | H28: Fall 2025 | I28: CSEE 4119_ An Introduction to Computer Networks (Fall 2025).pdf | J28: Prohibitive | K28: Not specified | L28: Instructor decides | M28: Academic Integrity | N28: Pedagogy/Learning | O28: Explicit penalties | P28: Students only | Q28: "The use of ChatGPT or any other generative artificial intelligence (AI) tools at any stage of the work process, including preliminary stages, is strictly prohibited. Violations of this policy will be considered academic misconduct." | S28: EY | T28: 46137 | U28: YM
A29: NYC-025 | B29: Course-wide | C29: NYC | D29: Columbia Course 2 | E29: Columbia | F29: PSYC UN1610: Intro to Statistics for Behavioral Scientists | G29: Syllabus | H29: Fall 2025 | I29: Fall 2025 Syllabus UN1610 Fox-Glassman Statistics for Behavioral Scientists.pdf | J29: Prohibitive | K29: Not specified | L29: Instructor decides | M29: Pedagogy/Learning | N29: Academic Integrity | O29: Explicit penalties | P29: Students only | Q29: "“Doing your own work” means making at attempt at each problem without the support of AI. There are lots of tools that can do stats problems for you. You will do best in this course if you use these only for checking your work; you will have a very bad time if you regularly replace the process of learning the material with a tendency to let AI tell you the answer." | S29: EY | T29: 46137
A30: NYC-026 | B30: Course-wide | C30: NYC | D30: Columbia Course 3 | E30: Columbia | F30: COMS 4705: Natural Language Processing | G30: Syllabus | H30: Fall 2025 | I30: COMS 4705_ Natural Language Processing.pdf | J30: Encouraging | K30: Not specified | L30: Instructor decides | M30: Professional Readiness | N30: AI Literacy | O30: Referenced to integrity code | P30: Students only | Q30: "AI tools (e.g., ChatGPT, Cursor, Claude Code) are fully allowed for Assignments 1–4. While I recommend doing the assignments on your own (or with minimal AI hints) as prep for exams, you may use AI to fully solve them if you wish." | S30: EY | T30: 46137
A31: NYC-027 | B31: Course-wide | C31: NYC | D31: Columbia/TC Course 4 | E31: Columbia | F31: HUDK 4051 Learning Analytics: Process and Theory | G31: Syllabus | H31: Summer 2024 | I31: HUDK4051_Sp26_Syllabus_Yu.pdf | J31: Encouraging | K31: Required | L31: Instructor decides | M31: Professional Readiness | N31: AI Literacy | O31: Referenced to integrity code | P31: Students only | Q31: "Generative AI tools are encouraged in this course for research and completion of assignments, provided that all AI-generated content is clearly attributed as such in the student’s work." | S31: EY | T31: 46137
A32: NYC-028 | B32: Course-wide | C32: NYC | D32: Columbia Course 5 | E32: Columbia | F32: COMS 4160: Introduction to Computer Graphics | G32: Syllabus | H32: Fall 2025 | I32: COMS 4160 — Introduction to Computer Graphics (Fall 2025).pdf | J32: Functional | K32: Conditional | L32: Instructor decides | M32: Academic Integrity | N32: Pedagogy/Learning | O32: Referenced to integrity code | P32: Students only | Q32: “You should not use generative AI to produce the solution to any of the assignments. You are allowed to use generative AI to produce your final project image (but do not lie about it if asked).”
A33: NYC-029 | B33: Course-wide | C33: NYC | D33: Columbia Course 6 | E33: Columbia | F33: Generative AI for Business | G33: Syllabus | H33: Fall 2025 | I33: olivier toubia - B8609 Generative AI for Business Fall 2025 Toubia.pdf | J33: Functional | K33: Required | L33: Instructor decides | M33: AI Literacy | N33: Academic Integrity | O33: Referenced to integrity code | P33: Students only | Q33: “You will use Generative AI tools for your work in this course. When you use any of these tools to complete assignments, you must describe how you used them to generate your response to the assignment.”
A34: NYC-030 | B34: Course-wide | C34: NYC | D34: NYU Course 1 | E34: NYU | F34: Programming & Algorithms using Python - Stern | G34: Syllabus | H34: Fall 2025 | I34: 2025Programming_in_Python_Software_DevSosulski (1).pdf | J34: Functional | K34: Required | L34: Instructor decides | M34: Professional Readiness | N34: Pedagogy/Learning | O34: Referenced to integrity code | P34: Students only | Q34: "Large language models (LLMS) may be used in this class, however you must cite it as you would any other reference material. Failure to acknowledge that content was GenAI generated will be considered a violation of academic integrity." | S34: EY | T34: 46137
A35: NYC-031 | B35: Course-wide | C35: NYC | D35: NYU Course 2 | E35: NYU | F35: Global Strategy - Stern | G35: Syllabus | H35: Fall 2025 | I35: MGMT-GB.2340_10_F2026.pdf | J35: Prohibitive | K35: Required | L35: Instructor decides | M35: Pedagogy/Learning | N35: Academic Integrity | O35: Explicit penalties | P35: Students only | Q35: "Your thoughts, opinions, and personal experiences are integral part of the learning process. As such, the use of generative AI is prohibited in this class. In this class, students are to engage in authentic self-reflection and genuine thinking." | S35: EY | T35: 46137 | U35: cy
A36: NYC-032 | B36: Course-wide | C36: NYC | D36: NYU Course 3 | E36: NYU | F36: Tax Policy Seminar - NYU Law | G36: Syllabus | H36: Spring 2026 | I36: Tax Policy Seminar Syllabus NYU Spring 2026_2DF65D21-D8A0-861C-BF9EDC4A13E27F5A.pdf | J36: Encouraging | K36: Required | L36: Instructor decides | M36: Academic Integrity | N36: Pedagogy/Learning | O36: Referenced to integrity code | P36: Students only | Q36: "That being said, for purposes of this course, for the response papers (only), the use of large language models/generative AI is expressly permitted as long as (a) you put in red font any material generated by AI; (b) you check any AI-generated content and take full responsibility for it as your written work product; and (c) you disclose and describe your use of AI with a general prefatory note or footnote indicating what background material you provided to the large language model, what prompts you used, and any revisions you made to AI-generated content." | S36: EY | T36: 46137 | U36: cy
A37: NYC-033 | B37: Course-wide | C37: NYC | D37: NYU Course 4 | E37: NYU | F37: Environmental Justice Seminar - NYU Law | G37: Syllabus | H37: Spring 2026 | I37: Early syllabus Spring 2026_33DBB621-E564-129B-AD1D4CB561DDC5F8.pdfg | J37: Cautious | K37: Not specified | L37: Instructor decides | M37: Pedagogy/Learning | N37: Academic Integrity | O37: Guidance only | P37: Students only | Q37: "Students should not use ChatGPT or other generative AI tools as a shortcut or substitute for coming up with their own answers to the prompts. Use of AI tools to help gather information should be done with caution." | S37: EY | T37: 46137
A38: NYC-034 | B38: Course-wide | C38: NYC | D38: NYU Course 5 | E38: NYU | F38: ENVIRONMENTAL JUSTICE SEMINAR | G38: Syllabus | H38: Spring 2026 | I38: ENVIRONMENTAL JUSTICE SEMINAR.pdf | J38: Cautious | K38: Not specified | L38: Instructor decides | M38: Pedagogy/Learning | N38: Academic Integrity | O38: Guidance only | P38: Students only | Q38: In this assignment, we are expecting students to think critically about the issues on their own and in collaboration with their group members. Students should not use ChatGPT or other generative AI tools as a shortcut or substitute for coming up with their own answers to the prompts. Use of AI tools to help gather information should be done with caution.
A39: NYC-035 | B39: Course-wide | C39: NYC | D39: NYU Course 6 | E39: NYU | F39: Foundations of FinTech | G39: Syllabus | H39: Fall 2024 | I39: 2024FoF-Fall2024-Sec10-syllabus-2024-10-10.pdf | J39: Functional | K39: Required | L39: Instructor decides | M39: Academic Integrity | N39: Pedagogy/Learning | O39: Explicit penalties | P39: Students only | Q39: “You can use AI at your own risk, but you are responsible for the accuracy and integrity of anything that you submit.”
A40: NYC-036 | B40: Course-wide | C40: NYC | D40: CUNY — Course 1 | E40: CUNY | F40: MATH 190: College Algebra | G40: Syllabus | H40: 2025 | I40: Syllabus_190.pdf | J40: Functional | K40: Required | L40: Instructor decides | M40: Pedagogy/Learning | N40: Academic Integrity | O40: Referenced to integrity code | P40: Students only | Q40: "You may use generative AI tools (such as ChatGPT) to assist with homework in this course, provided you clearly indicate when and how AI was used, including the specific tool and model. All submitted work must reect your own understandingyou are responsible for checking and explaining any AI-assisted solutions." | S40: EY | T40: 46137 | U40: cy
A41: NYC-037 | B41: Course-wide | C41: NYC | D41: CUNY — Course 2 | E41: CUNY | F41: ENV 3070: Agroecology | G41: Syllabus | H41: Fall 2025 | I41: viewcontent.pdf | J41: Functional | K41: Required | L41: Instructor decides | M41: Pedagogy/Learning | N41: Academic Integrity | O41: Referenced to integrity code | P41: Students only | Q41: "Use of generative AI tools (e.g. ChatGPT) is allowed. For each written assignment where generative AI is employed, you must include a cover letter describing what tool(s) you used, how you used it, why it was useful, and any shortcomings or limitations you encountered." | S41: EY | T41: 46137
A42: NYC-038 | B42: Course-wide | C42: NYC | D42: CUNY — Course 3 | E42: CUNY | F42: Psychology 32: Human Growth and Development | G42: Syllabus | H42: 2025 | I42: Psych32.pdf | J42: Functional | K42: Required | L42: Instructor decides | M42: Pedagogy/Learning | N42: Academic Integrity | O42: Referenced to integrity code | P42: Students only | Q42: "The use of generative AI tools is permitted in this course for the following activities: Brainstorming and researching; Drafting an outline; Organizing your thoughts; Checking grammar. Please cite the AI tool you use, if used. Please share the date of access and the specific prompt or query you used to generate the output received by AI" | S42: EY | T42: 46137 | U42: cy
...

Sheet NEW_NYC_Coding
A1: NYC Coding — GenAI Policy Coding
A4: ID | B4: Tier | C4: Region | D4: Jurisdiction / Institution | E4: Institution | F4: Document Title | G4: Document Type | H4: Publication Date | I4: Source URL | J4: Stance | K4: Disclosure | L4: Discretion | M4: Focus (Primary) | N4: Focus (Secondary) | O4: Enforcement | P4: Coverage | Q4: Key Quote (verbatim) | R4: Coder Notes | S4: Coder | T4: Date Coded | U4: Coder Agreement (Initials if agree and Comment if disagree)
A5: NYC-001 | B5: National/Federal | C5: NYC | D5: US Federal (White House) | F5: National Policy Framework for Artificial Intelligence | G5: Executive Order | H5: 46376 | I5: https://www.whitehouse.gov/wp-content/uploads/2026/03/03.20.26-National-Policy-Framework-for-Artificial-Intelligence-Legislative-Recommendations.pdf | J5: Functional | K5: Not specified | L5: Gov-mandated | M5: Professional Readiness | N5: AI Literacy | O5: Guidance only | P5: Whole community | Q5: “The federal government must establish a federal AI policy framework to protect American rights, support innovation, and prevent a fragmented patchwork of state regulations.” | S5: EY | T5: 46157 | V5: {=XLOOKUP($I5,TEST_NYC_Coding!$I$5:$I$44,TEST_NYC_Coding!$A$5:$A$44,"")}
A6: NYC-002 | B6: National/Federal | C6: NYC | D6: US Federal (White House) | F6: Executive Order: Eliminating State Law Obstruction of National AI Policy | G6: Executive Order | H6: 45973 | I6: https://www.whitehouse.gov/presidential-actions/2025/12/eliminating-state-law-obstruction-of-national-artificial-intelligence-policy/ | J6: Encouraging | K6: Not specified | L6: Gov-mandated | M6: Professional Readiness | N6: AI Literacy | O6: Guidance only | P6: Whole community | Q6: It is the policy of the United States to sustain and enhance the United States’ global AI dominance through a minimally burdensome national policy framework for AI. | S6: EY | T6: 46157 | V6: {=XLOOKUP($I6,TEST_NYC_Coding!$I$5:$I$44,TEST_NYC_Coding!$A$5:$A$44,"")}
A7: NYC-003 | B7: National/Federal | C7: NYC | D7: ACUS (Administrative Conference of the United States) | F7: ACUS Policy on Use of Generative AI | G7: Law/Regulation | H7: 45942 | I7: https://www.acus.gov/sites/default/files/documents/ACUS_Policy_on_Use_of_GenAI-20251210.pdf | J7: Cautious | K7: Required | L7: Gov-mandated | M7: Privacy/Data/Ethics | N7: Academic Integrity | O7: Referenced to integrity code | P7: Whole community | Q7: Federal employees must disclose GenAI use and must not input sensitive or confidential information into public AI tools | S7: EY | T7: 46157 | V7: {=XLOOKUP($I7,TEST_NYC_Coding!$I$5:$I$44,TEST_NYC_Coding!$A$5:$A$44,"")}
A8: NYC-004 | B8: National/Federal | C8: NYC | D8: US Federal (White House) | F8: Advancing Artificial Intelligence Education for American Youth | G8: Executive Order | H8: 45770 | I8: https://www.whitehouse.gov/presidential-actions/2025/04/advancing-artificial-intelligence-education-for-american-youth/ | J8: Encouraging | K8: Not specified | L8: Gov-mandated | M8: Professional Readiness | N8: Pedagogy/Learning | O8: Guidance only | P8: Whole community | Q8: “It is the policy of the United States to promote AI literacy and proficiency among Americans by promoting the appropriate integration of AI into education, providing comprehensive AI training for educators, and fostering early exposure to AI concepts and technology to develop an AI-ready workforce and the next generation of American AI innovators.” | S8: EY | T8: 46157 | V8: {=XLOOKUP($I8,TEST_NYC_Coding!$I$5:$I$44,TEST_NYC_Coding!$A$5:$A$44,"")}
A9: NYC-005 | B9: National/Federal | C9: NYC | D9: US Federal (White House) | F9: Ensuring a National Policy Framework for AI | G9: Executive Order | H9: 46002 | I9: https://www.whitehouse.gov/presidential-actions/2025/12/eliminating-state-law-obstruction-of-national-artificial-intelligence-policy/ | J9: Encouraging | K9: Not specified | L9: Gov-mandated | M9: Professional Readiness | N9: Privacy/Data/Ethics | O9: Explicit penalties | P9: Whole community | Q9: “United States AI companies must be free to innovate without cumbersome regulation.” | S9: EY | T9: 46157 | V9: {=XLOOKUP($I9,TEST_NYC_Coding!$I$5:$I$44,TEST_NYC_Coding!$A$5:$A$44,"")}
A10: NYC-006 | B10: City/Territory | C10: NYC | D10: NYC — Office of Technology and Innovation (OTI) | E10: OTI | F10: NYC Use Guidance: Generative Artificial Intelligence | G10: Official Guidance | H10: 30/2/2025 | I10: https://www.nyc.gov/assets/oti/downloads/pdf/New-York-City-Generative-AI-Use-Guidance.pdf | J10: Cautious | K10: Required | L10: Gov-mandated | M10: Privacy/Data/Ethics | N10: AI Literacy | O10: Guidance only | P10: Whole community | Q10: "The City is committed to a responsible approach to emerging technologies. This Use Guidance provides a framework for the responsible use of GenAI by City personnel, aligned with the City’s AI Principles, and applicable laws and policies." | S10: EY | V10: {=XLOOKUP($I10,TEST_NYC_Coding!$I$5:$I$44,TEST_NYC_Coding!$A$5:$A$44,"")} -> NYC-008
A11: NYC-007 | B11: City/Territory | C11: NYC | D11: New York City — Office of Technology and Innovation (OTI), Strategic Initiatives Division | E11: OTI | F11: Preliminary Use Guidance: Generative Artificial Intelligence | G11: Official Guidance | H11: 45352 | I11: https://www.nyc.gov/assets/oti/downloads/pdf/about/preliminary-use-guidance-general-artificial-intelligence.pdf | J11: Cautious | K11: Required | L11: Gov-mandated | M11: Privacy/Data/Ethics | N11: AI Literacy | O11: Referenced to integrity code | P11: Whole community | Q11: In order to support critical engagement by end users and maintain public trust in city government, it is best practice to proactively disclose the use of Generative AI in all contexts | S11: EY | V11: {=XLOOKUP($I11,TEST_NYC_Coding!$I$5:$I$44,TEST_NYC_Coding!$A$5:$A$44,"")}
A12: NYC-008 | B12: City/Territory | C12: NYC | D12: NYC Office of Technology and Innovation | E12: OTI | F12: NYC Artificial Intelligence Action Plan | G12: Official Guidance | I12: https://www.nyc.gov/assets/oti/downloads/pdf/reports/artificial-intelligence-action-plan.pdf | J12: Cautious | K12: Not specified | L12: Gov-mandated | M12: Privacy/Data/Ethics | N12: AI Literacy | O12: Guidance only | P12: Whole community | Q12: “The NYC AI Action Plan introduces seven new initiatives… toward harnessing the power of AI to deliver positive outcomes for New Yorkers, while carefully mitigating the risks these technologies present.” | S12: EY | V12: {=XLOOKUP($I12,TEST_NYC_Coding!$I$5:$I$44,TEST_NYC_Coding!$A$5:$A$44,"")}
A13: NYC-009 | B13: City/Territory | C13: NYC | D13: NYC Office of Technology and Innovation | E13: OTI | F13: NYC AI Action Plan Annual Progress Report - 2025 | G13: Other | H13: 45946 | I13: https://www.nyc.gov/assets/oti/downloads/pdf/AI-Action-Plan-Progress-Report-Year-2.pdf | J13: Cautious | K13: Not specified | L13: Gov-mandated | M13: Privacy/Data/Ethics | N13: AI Literacy | O13: None stated | P13: Whole community | Q13: “The Action Plan included 37 actions across seven initiatives focused on supporting city agencies’ efforts to understand and use AI tools, fostering appropriate governance across the city…” | S13: EY | V13: {=XLOOKUP($I13,TEST_NYC_Coding!$I$5:$I$44,TEST_NYC_Coding!$A$5:$A$44,"")}
A14: NYC-010 | B14: City/Territory | C14: NYC | D14: NYC Public Schools | E14: NYCPS | F14: NYC Public Schools (NYCPS) AI Guidance | G14: Other | H14: 46082 | I14: https://www.schools.nyc.gov/about-us/vision-and-mission/artificial-intelligence/guidance-on-artificial-intelligence-full | J14: Cautious | K14: Required | L14: Hybrid | M14: AI Literacy | N14: Pedagogy/Learning | O14: Referenced to integrity code | P14: Whole community | Q14: “The NYCPS Traffic Light Approach… establishes when AI use is prohibited, when AI use requires careful consideration and judgment, and when AI is approved for use.” | S14: EY | V14: {=XLOOKUP($I14,TEST_NYC_Coding!$I$5:$I$44,TEST_NYC_Coding!$A$5:$A$44,"")}
A15: NYC-011 | B15: Institutional | C15: NYC | D15: New York University | E15: NYU | F15: NYU Information Technology AI Primer | G15: FAQ/Resource Page | I15: https://www.nyu.edu/life/information-technology/artificial-intelligence-at-nyu/primer.html | J15: Functional | K15: Not specified | L15: Not specified | M15: AI Literacy | N15: Privacy/Data/Ethics | O15: Guidance only | P15: Whole community | Q15: While the models are immensely powerful tools, they require careful integration, governance, and human oversight to manage issues like bias, misinformation (hallucinations), and intellectual property, ensuring their power is used responsibly. | S15: EY | V15: {=XLOOKUP($I15,TEST_NYC_Coding!$I$5:$I$44,TEST_NYC_Coding!$A$5:$A$44,"")}
A16: NYC-012 | B16: Institutional | C16: NYC | D16: New York University | E16: NYU | F16: Student Learning with Generative AI | G16: FAQ/Resource Page | I16: https://www.nyu.edu/faculty/teaching-and-learning-resources/Student-Learning-with-Generative-AI.html | J16: Functional | K16: Recommended | L16: Institution-mandated | M16: AI Literacy | N16: Pedagogy/Learning | O16: Guidance only | P16: Students and Faculty | Q16: Students and faculty may use AI tools for learning and research; they should understand how AI works, evaluate outputs critically, and cite AI use where appropriate | S16: EY | V16: {=XLOOKUP($I16,TEST_NYC_Coding!$I$5:$I$44,TEST_NYC_Coding!$A$5:$A$44,"")}
A17: NYC-013 | B17: Institutional | C17: NYC | D17: New York University | E17: NYU | F17: Adapting Assignments to Generative AI | G17: University Policy | I17: https://www.nyu.edu/faculty/teaching-and-learning-resources/teaching-with-generative-tools/adapting-assignments-to-generative-AI.html | J17: Functional | K17: Recommended | L17: Instructor decides | M17: AI Literacy | N17: Academic Integrity | O17: Referenced to integrity code | P17: Faculty only | Q17: Even if an instructor does not intend to change individual assignments, the availability and generality of these tools increases the need for clarity around the instructor’s expectations. Whatever strategies an instructor might adopt for individual assignments or a whole course, instructors should explain to students what is expected around AI use. | S17: EY | V17: {=XLOOKUP($I17,TEST_NYC_Coding!$I$5:$I$44,TEST_NYC_Coding!$A$5:$A$44,"")}
A18: NYC-014 | B18: Institutional | C18: NYC | D18: New York University | E18: NYU | F18: Frequently Asked Questions About Teaching and AI | G18: FAQ/Resource Page | H18: 45708 | I18: https://www.nyu.edu/faculty/teaching-and-learning-resources/teaching-with-generative-tools/frequently-asked-questions.html | J18: Functional | K18: Recommended | L18: Instructor decides | M18: Pedagogy/Learning | N18: Academic Integrity | O18: Guidance only | P18: Faculty only | Q18: "Generative AI is a new arrival in the academic environment and can be used in a wide variety of ways. Because of this novelty and flexibility, there are few standard approaches to its use beyond an Faculty/Inst. decides restriction on taking credit for AI output without acknowledging its use. Most policies will be set by the schools or by individual faculty members." | S18: EY | V18: {=XLOOKUP($I18,TEST_NYC_Coding!$I$5:$I$44,TEST_NYC_Coding!$A$5:$A$44,"")} -> NYC-012
A19: NYC-015 | B19: Institutional | C19: NYC | D19: New York University | E19: NYU | F19: NYU AI Center of Excellence | G19: FAQ/Resource Page | I19: https://www.nyu.edu/life/information-technology/artificial-intelligence-at-nyu/coe.html | J19: Encouraging | K19: Not specified | L19: Institution-mandated | M19: AI Literacy | N19: Pedagogy/Learning | O19: Guidance only | P19: Whole community | Q19: “New York University is strategically investing in AI to gain significant administrative efficiencies, accelerate cutting-edge research, and equip our entire community—faculty, students, and staff—with the tools to thrive in an AI-driven world.” | S19: EY | V19: {=XLOOKUP($I19,TEST_NYC_Coding!$I$5:$I$44,TEST_NYC_Coding!$A$5:$A$44,"")}
A20: NYC-016 | B20: Institutional | C20: NYC | D20: City University of New York | E20: CUNY | F20: CUNY AI Academic Hub | G20: University Policy | H20: 2025 | I20: https://www.cuny.edu/academics/ai-academic-hub/ | J20: Encouraging | K20: Not specified | L20: Not specified | M20: AI Literacy | N20: Professional Readiness | O20: Guidance only | P20: Students and Faculty | Q20: "Our Vision is shaping the Future of Human-AI Powered Education. CUNY is at the forefront of AI-driven transformation in higher education. Our mission is to harness AI’s potential to empower learning, drive research, and foster innovation—ensuring equitable opportunities for all." | S20: EY | V20: {=XLOOKUP($I20,TEST_NYC_Coding!$I$5:$I$44,TEST_NYC_Coding!$A$5:$A$44,"")} -> NYC-017
A21: NYC-017 | B21: Institutional | C21: NYC | D21: City University of New York | E21: CUNY | F21: Teach@CUNY AI Toolkit | G21: FAQ/Resource Page | I21: https://aitoolkit.commons.gc.cuny.edu/ | J21: Cautious | K21: Recommended | L21: Instructor decides | M21: AI Literacy | N21: Pedagogy/Learning | O21: Guidance only | P21: Students and Faculty | Q21: “This toolkit offers guidelines and resources to help instructors support students as we all learn to navigate a world increasingly awash in AI.” | S21: EY | V21: {=XLOOKUP($I21,TEST_NYC_Coding!$I$5:$I$44,TEST_NYC_Coding!$A$5:$A$44,"")}
A22: NYC-018 | B22: Institutional | C22: NYC | D22: City University of New York | E22: CUNY | F22: CUNY Central Academic Integrity Policy | G22: University Policy | H22: 2024 | I22: https://www.cuny.edu/about/administration/offices/legal-affairs/policies-resources/academic-integrity-policy/ | J22: Cautious | K22: Required | L22: Hybrid | M22: Academic Integrity | N22: AI Literacy | O22: Explicit penalties | P22: Students and Faculty | Q22: “Any use of generative AI tools must be in line with the usage policy for specific assignments as defined in the course of the syllabus and/or communicated by the course instructor.” | S22: EY | V22: {=XLOOKUP($I22,TEST_NYC_Coding!$I$5:$I$44,TEST_NYC_Coding!$A$5:$A$44,"")}
A23: NYC-019 | B23: Institutional | C23: NYC | D23: City University of New York | E23: CUNY | F23: AI Across CUNY | G23: FAQ/Resource Page | H23: 45930 | I23: https://www.ccny.cuny.edu/tlc/making-your-course-available?srsltid=AfmBOoojIHHL2OxDCdrK-0Xc9elMyrAnNWVcOtEzwybtMdTvH4Pbcfy- | J23: Encouraging | K23: Required | L23: Instructor decides | M23: AI Literacy | N23: Pedagogy/Learning | O23: None stated | P23: Students and Faculty | Q23: “The Teaching and Learning Center developed this resource to help faculty explore the intersection of AI and education.” | S23: EY | V23: {=XLOOKUP($I23,TEST_NYC_Coding!$I$5:$I$44,TEST_NYC_Coding!$A$5:$A$44,"")} -> NYC-020
A24: NYC-020 | B24: Institutional | C24: NYC | D24: City University of New York | CUNY Central Office / CUNY Innovative Teaching Academy | E24: CUNY | F24: Teaching with AI: Disciplinary Toolkits | G24: FAQ/Resource Page | H24: 2024-2025 | I24: https://www.cuny.edu/academics/faculty-affairs/faculty-hub/cuny-innovative-teaching-academy/building-bridges-of-knowledge-bbk/#1743443301057-e01b194c-474d | J24: Encouraging | K24: Not specified | L24: Instructor decides | M24: AI Literacy | N24: Professional Readiness | O24: None stated | P24: Students and Faculty | Q24: “Building Bridge of Knowledge (BBK) is a CUNY-wide faculty fellowship project, aiming to help students use generative artificial intelligence (AI) tools ethically, responsibly, and effectively.” | S24: EY | V24: {=XLOOKUP($I24,TEST_NYC_Coding!$I$5:$I$44,TEST_NYC_Coding!$A$5:$A$44,"")}
A25: NYC-021 | B25: Institutional | C25: NYC | D25: Columbia University / Office of the Provost | E25: Columbia | F25: Office of the Provost: Generative AI Policy & Guidance (2024-2026) | G25: University Policy | I25: https://provost.columbia.edu/content/generative-ai | J25: Cautious | K25: Required | L25: Hybrid | M25: Privacy/Data/Ethics | N25: Academic Integrity | O25: Referenced to integrity code | P25: Whole community | Q25: “Columbia recognizes that generative AI is a tool that is transforming higher education and society, and encourages our campus community to explore its possibilities while being mindful of the potential security and privacy risks that it poses.” | S25: EY | V25: {=XLOOKUP($I25,TEST_NYC_Coding!$I$5:$I$44,TEST_NYC_Coding!$A$5:$A$44,"")}
A26: NYC-022 | B26: Institutional | C26: NYC | D26: Columbia University Information Technology / Emerging Technologies | E26: Columbia | F26: Best Practices for Responsible AI Use | G26: University Policy | H26: 46031 | I26: https://etc.cuit.columbia.edu/news/best-practices-responsible-ai-use | J26: Cautious | K26: Required | L26: Hybrid | M26: Privacy/Data/Ethics | N26: AI Literacy | O26: Referenced to integrity code | P26: Whole community | Q26: CUIT’s guidance is designed to help the Columbia community benefit from AI while avoiding common failure points, particularly when institutional or sensitive data is involved. At the center of the guidance is one principle: AI should assist human judgment, not replace i | S26: EY | V26: {=XLOOKUP($I26,TEST_NYC_Coding!$I$5:$I$44,TEST_NYC_Coding!$A$5:$A$44,"")} -> NYC-011
A27: NYC-023 | B27: Institutional | C27: NYC | D27: Columbia University | E27: Columbia | F27: Columbia CTL AI Guidelines (2024-2026) | G27: University Policy | I27: https://ctl.columbia.edu/resources-and-technology/resources/academic-integrity/ | J27: Cautious | K27: Required | L27: Instructor decides | M27: Academic Integrity | N27: AI Literacy | O27: Referenced to integrity code | P27: Students and Faculty | Q27: “The possible advantages that might present in the teaching-learning process should be under the control of each instructor since they know exactly what they expect from students’ work.” | S27: EY | V27: {=XLOOKUP($I27,TEST_NYC_Coding!$I$5:$I$44,TEST_NYC_Coding!$A$5:$A$44,"")}
A28: NYC-024 | B28: Institutional | C28: NYC | D28: Columbia University | E28: Columbia | F28: CUIT AI Framework Policy | G28: FAQ/Resource Page | H28: 45818 | I28: https://www.cuit.columbia.edu/sites/www.cuit.columbia.edu/files/content/CUIT%20Website%20Pages/AI%20Framework%20%20(1).pdf | J28: Encouraging | K28: Recommended | L28: Institution-mandated | M28: Privacy/Data/Ethics | O28: Guidance only | P28: Whole community | Q28: “A key tenet of the framework is governance — ensuring that all AI initiatives adhere to security, privacy, and compliance requirements from the outset.” | S28: EY | V28: {=XLOOKUP($I28,TEST_NYC_Coding!$I$5:$I$44,TEST_NYC_Coding!$A$5:$A$44,"")}
A29: NYC-025 | B29: Institutional | C29: NYC | D29: Columbia University | E29: Columbia | F29: CUIT Generative AI Data Security Guidelines | G29: University Policy | I29: https://www.cuit.columbia.edu/content/ai-services | J29: Encouraging | K29: Not specified | L29: Institution-mandated | M29: AI Literacy | O29: Guidance only | P29: Whole community | Q29: “For work involving non-public data, Columbia IT maintains a set of enterprise-grade AI tools — including Columbia ChatGPT Education, CHAT, and Google for Education — that operate within a secured environment sometimes called a ‘walled garden.’” | S29: EY | V29: {=XLOOKUP($I29,TEST_NYC_Coding!$I$5:$I$44,TEST_NYC_Coding!$A$5:$A$44,"")}
A30: NYC-026 | B30: Faculty/Department | C30: NYC | D30: New York University - Steinhardt | E30: NYU | F30: NYU Steinhardt - Academic Integrity and Syllabus Support in the Age of Generative AI | G30: FAQ/Resource Page | I30: https://steinhardt.nyu.edu/faculty-and-staff/academic-affairs/steinhardt-ai-hub/academic-integrity-and-syllabus-support-age | J30: Cautious | K30: Required | L30: Faculty/Dept decides | M30: AI Literacy | N30: Pedagogy/Learning | O30: Referenced to integrity code | P30: Faculty only | Q30: “Any AI-generated content used in assignments must be properly attributed.” | S30: EY | T30: 46157 | V30: {=XLOOKUP($I30,TEST_NYC_Coding!$I$5:$I$44,TEST_NYC_Coding!$A$5:$A$44,"")} -> NYC-013
A31: NYC-027 | B31: Faculty/Department | C31: NYC | D31: New York University - CAS | E31: NYU | F31: CAS - Expository Writing Program (EWP) Statement on AI (2026) | G31: University Policy | H31: 45962 | I31: https://cas.nyu.edu/ewp/about/statement-on-generative-ai.html | J31: Prohibitive | K31: Conditional | L31: Hybrid | M31: Pedagogy/Learning | N31: Academic Integrity | O31: Guidance only | P31: Students and Faculty | Q31: No EWP class permits students to use AI-generated writing unless it is clearly identified as an object for analysis | S31: EY | T31: 46157 | V31: {=XLOOKUP($I31,TEST_NYC_Coding!$I$5:$I$44,TEST_NYC_Coding!$A$5:$A$44,"")}
A32: NYC-028 | B32: Faculty/Department | C32: NYC | D32: New York University | E32: NYU | F32: Academic Integrity - Tisch | G32: University Policy | I32: https://tisch.nyu.edu/faculty/academic-integ | J32: Cautious | K32: Not specified | L32: Instructor decides | M32: Academic Integrity | N32: Pedagogy/Learning | O32: Explicit penalties | P32: Students and Faculty | Q32: Generative AI: Please note, with recent developments in technologies like ChatGPT, the existence of a well-written paragraph is no longer evidence of human effort. To read the Provost's notes on how to adapt writing assignments in the age of generative AI, click here. | S32: EY | T32: 46157 | V32: {=XLOOKUP($I32,TEST_NYC_Coding!$I$5:$I$44,TEST_NYC_Coding!$A$5:$A$44,"")} -> NYC-015
A33: NYC-029 | B33: Faculty/Department | C33: NYC | D33: New York University | E33: NYU | F33: Generative AI Updates – Live Syllabus and Faculty Development Resources | G33: FAQ/Resource Page | H33: 45314 | I33: https://wp.nyu.edu/fas-edtech/2024/01/generative-ai-updates-live-syllabus-and-faculty-development-resources/ | J33: Cautious | K33: Recommended | L33: Instructor decides | M33: Pedagogy/Learning | N33: Academic Integrity | O33: Guidance only | P33: Faculty only | Q33: “Whatever your approach, clear communication with students about your expectations and your justification for your generative AI use policies should be on your beginning of the semester agenda.” | S33: EY | T33: 46157 | V33: {=XLOOKUP($I33,TEST_NYC_Coding!$I$5:$I$44,TEST_NYC_Coding!$A$5:$A$44,"")}
A34: NYC-030 | B34: Faculty/Department | C34: NYC | D34: New York University | E34: NYU | F34: Generative AI Resources for Faculty - NYU Arts and Sciences | G34: FAQ/Resource Page | I34: https://as.nyu.edu/academics/teaching-excellence-and-innovation/services/course-support/genai-resources.html | J34: Cautious | K34: Not specified | L34: Instructor decides | M34: AI Literacy | N34: Academic Integrity | O34: Guidance only | P34: Faculty only | Q34: “The materials on this page are a regularly updated collection of the advice and resources our team shares with instructors and departments about AI and teaching and learning.” | S34: EY | T34: 46157 | V34: {=XLOOKUP($I34,TEST_NYC_Coding!$I$5:$I$44,TEST_NYC_Coding!$A$5:$A$44,"")}
A35: NYC-031 | B35: Faculty/Department | C35: NYC | D35: CUNY - Baruch College | E35: CUNY | F35: Guidelines for AI Use at Baruch College | G35: Official Guidance | H35: 45888 | I35: https://provost.baruch.cuny.edu/artificial-intelligence-think-tank/ai-use-guidance/ | J35: Encouraging | K35: Required | L35: Instructor decides | M35: Pedagogy/Learning | N35: Privacy/Data/Ethics | O35: Referenced to integrity code | P35: Students and Faculty | Q35: "Faculty are encouraged to integrate artificial intelligence education into their courses as appropriate to their disciplines, but are not obligated to do so. All syllabi should include a course- and discipline-appropriate policy on the use of generative AI." | S35: EY | T35: 46157 | V35: {=XLOOKUP($I35,TEST_NYC_Coding!$I$5:$I$44,TEST_NYC_Coding!$A$5:$A$44,"")} -> NYC-018
A36: NYC-032 | B36: Faculty/Department | C36: NYC | D36: CUNY - John Jay College of Criminal Justice | E36: CUNY | F36: AI Responsible Use Guidelines | G36: Official Guidance | I36: https://www.jjay.cuny.edu/about/senior-leadership/academic-affairs/office-provost/ai-policies-guidelines | J36: Functional | K36: Required | L36: Institution-mandated | M36: Academic Integrity | N36: AI Literacy | O36: Referenced to integrity code | P36: Whole community | Q36: Generative AI is a powerful tool for research and scholarship, and its effective use is becoming an essential workplace skill. We believe that fostering AI literacy across all disciplines is an extension of our mission to prepare students for meaningful careers and ethical leadership within the justice system and beyond. | R36: There are 3 documents, For Everyone, For Student and For Faculty. All of them were considered in this coding | S36: EY | T36: 46157 | V36: {=XLOOKUP($I36,TEST_NYC_Coding!$I$5:$I$44,TEST_NYC_Coding!$A$5:$A$44,"")}
A37: NYC-033 | B37: Faculty/Department | C37: NYC | D37: CUNY - LaGuardia | E37: CUNY | F37: Teaching Writing at LaGuardia Generative AI Guidance. | G37: Official Guidance | I37: https://lagccwriting.commons.gc.cuny.edu/gen-ai-guidance/ | J37: Functional | K37: Recommended | L37: Instructor decides | M37: Pedagogy/Learning | N37: Academic Integrity | O37: Referenced to integrity code | P37: Students and Faculty | Q37: Please include a statement on your syllabus which indicates your policy about student use of AI in your class. Please also verbally reinforce this policy with students throughout the semester. Right now, the Department does not have a uniform policy. To help you decide on your policy, here are some guiding resources: | S37: EY | T37: 46157 | V37: {=XLOOKUP($I37,TEST_NYC_Coding!$I$5:$I$44,TEST_NYC_Coding!$A$5:$A$44,"")}
A38: NYC-034 | B38: Faculty/Department | C38: NYC | D38: CUNY - City Tech | E38: CUNY | F38: City Tech Artificial Intelligence Guidance | G38: Official Guidance | I38: https://www.citytech.cuny.edu/ai/ai-guidance.aspx | J38: Cautious | K38: Required | L38: Hybrid | M38: Privacy/Data/Ethics | N38: Academic Integrity | O38: Referenced to integrity code | P38: Whole community | Q38: City Tech recognizes the rapid evolution of Artificial Intelligence (AI) and its impact on how we work, teach and learn. As the landscape of AI changes, and Generative AI tools become widely available for everyday use, new opportunities in higher education are realized, but also present new risks that must be taken into consideration when using these technologies. We encourage you to experiment with AI tools, but also consider the following guidelines which align with existing CUNY and City Tech policies on information security and academic integrity. Please consider the guidelines in conjunction with other CUNY recommendations and policies. | R38: There are 3 documents, For Everyone, For Student and For Faculty. All of them were considered in this coding | S38: EY | T38: 46157 | V38: {=XLOOKUP($I38,TEST_NYC_Coding!$I$5:$I$44,TEST_NYC_Coding!$A$5:$A$44,"")}
A39: NYC-035 | B39: Faculty/Department | C39: NYC | D39: CUNY - Queens College | E39: CUNY | F39: Generative AI in the Classroom: Best Practices, a CETLL Guide | G39: FAQ/Resource Page | H39: 45717 | I39: https://www.qc.cuny.edu/cetll/wp-content/uploads/sites/138/2026/03/Generative-AI-in-the-Classroom-Best-Practices-a-CETLL-Guide_ACCESSIBLE_3.19.pdf | J39: Functional | K39: Recommended | L39: Instructor decides | M39: Pedagogy/Learning | N39: AI Literacy | O39: Guidance only | P39: Faculty only | Q39: Currently, there is no specific CUNY or QC policy on the use of artificial intelligence in the classroom outside of mentions of AI in the CUNY Academic Integrity Policy. This means that, as instructors, we have a lot of flexibility and responsibility to consider how and when the use of generative AI is acceptable in our classes to clearly communicate these parameters to our students as we prepare them for the integration of these technologies in work and life. | S39: EY | T39: 46157 | V39: {=XLOOKUP($I39,TEST_NYC_Coding!$I$5:$I$44,TEST_NYC_Coding!$A$5:$A$44,"")} -> NYC-022
A40: NYC-036 | B40: Faculty/Department | C40: NYC | D40: Teachers College, Columbia University | E40: Columbia | F40: TC Guidance - Developing a Generative AI Policy for Your Course | G40: FAQ/Resource Page | H40: 2025 | I40: https://www.tc.columbia.edu/digitalfuturesinstitute/ai-in-education/recommendations-for-generative-ai-use-at-tc/ | J40: Functional | K40: Conditional | L40: Instructor decides | M40: Pedagogy/Learning | N40: Academic Integrity | O40: Referenced to integrity code | P40: Students and Faculty | Q40: "TC provides flexibility for instructors to experiment with and use generative AI in their courses. Each TC instructor should set specific policies about student use of generative AI for their course assignments" | S40: EY | T40: 46156 | V40: {=XLOOKUP($I40,TEST_NYC_Coding!$I$5:$I$44,TEST_NYC_Coding!$A$5:$A$44,"")} -> NYC-023
A41: NYC-037 | B41: Faculty/Department | C41: NYC | D41: Columbia Law School | E41: Columbia | F41: Columbia Law School Interim Policy on Generative AI | G41: University Policy | I41: https://www.law.columbia.edu/academics/registration-services/resources/columbia-law-school-interim-policy-generative-ai | J41: Cautious | K41: Not specified | L41: Hybrid | M41: Academic Integrity | N41: AI Literacy | O41: Referenced to integrity code | P41: Students and Faculty | Q41: Generative AI includes any machine-based tool designed to help write, rewrite, or restructure language from user questions and prompts. Prohibited tools include, for example, Bard, ChatGPT, Gemini, Grok, along with embedded tools in programs such as Grammarly or Microsoft Copilot. Generative AI is distinct from software that helps search for and extract information from data sources for use in research. (...) Use of Generative AI is prohibited in (a) any exam or final paper or (b) for aid in drafting any part of work submitted for credit, even if the use is fully documented. The Law School and University Generative AI policies are default rules. This means individual instructors can, and indeed are encouraged to, tailor their own more permissive policies, so long as their policies are stated in writing in the syllabus. | S41: EY | T41: 46156 | V41: {=XLOOKUP($I41,TEST_NYC_Coding!$I$5:$I$44,TEST_NYC_Coding!$A$5:$A$44,"")}
A42: NYC-038 | B42: Faculty/Department | C42: NYC | D42: Columbia Business School | E42: Columbia | F42: Columbia Business School - Getting Started with Generative Artificial Intelligence | G42: University Policy | I42: https://business.columbia.edu/samberg/ai/ai-basics | J42: Encouraging | K42: Required | L42: Institution-mandated | M42: AI Literacy | N42: Privacy/Data/Ethics | O42: None stated | P42: Whole community | Q42: “Generative AI is a powerful tool capable of creating innovative solutions, automating repetitive tasks, and enhancing productivity.” | S42: EY | T42: 46156 | V42: {=XLOOKUP($I42,TEST_NYC_Coding!$I$5:$I$44,TEST_NYC_Coding!$A$5:$A$44,"")}
...

Sheet TEST_HK_Coding
A1: Hong Kong Coding — GenAI Policy Coding
A2: Fill one row per policy document. Use dropdowns wherever possible. See tab '5_Codebook' for definitions.
A4: ID | B4: Tier | C4: Region | D4: Jurisdiction / Institution | E4: Institution | F4: Document Title | G4: Document Type | H4: Publication Date | I4: Source URL | J4: Stance | K4: Disclosure | L4: Discretion | M4: Focus (Primary) | N4: Focus (Secondary) | O4: Enforcement | P4: Coverage | Q4: Key Quote (verbatim) | R4: Coder Notes | S4: Coder | T4: Date Coded | U4: Coder Agreement (Initials if agree and DONT AGREE) | V4: No AI (teaching content is not AI policy)
